Workbook

Sheet Instructions
B2: CSF Profile Template — Instructions
B5: PURPOSE
B7: SHEETS IN THIS WORKBOOK
B8: 1. Instructions: This page — how to use the workbook
B9: 2. Current Profile: Rate your organization's current state for each CSF outcome (1–4 scale)
B10: 3. Target Profile: Define your desired target state for each CSF outcome
B11: 4. Gap Analysis: Automatically calculated gap between current and target; prioritized roadmap
B12: 5. Tier Summary: Function-level tier summary and overall program tier
B14: HOW TO COMPLETE
B15: Step 1: Go to the 'Current Profile' sheet. For each row, enter your current implementation score (1–4).
B16: Step 2: Go to the 'Target Profile' sheet. Enter your desired target score for each outcome (1–4).
B17: Step 3: Review the 'Gap Analysis' sheet — gaps are auto-calculated. Prioritize High gaps.
... B26: NOTES

Sheet Current Profile
B1: NIST CSF 2.0 — Current Profile
B2: Organization: | G2: Date:
B3: Function | C3: Category | D3: Subcategory ID | E3: Subcategory Description | F3: Current Score | G3: Target Score | H3: Notes / Evidence Reference
E4: Rate current implementation 1=Partial 2=Risk Informed 3=Repeatable 4=Adaptive | F4: Enter 1–4 (or N/A) | G4: Enter 1–4 (or N/A) | H4: Document evidence or context
B5: ▶ GOVERN (GV)
B6: GOVERN | C6: Organizational Context | D6: GV.OC-01 | E6: Mission, stakeholders, and dependencies understood
B7: GOVERN | C7: Organizational Context | D7: GV.OC-02 | E7: Legal/regulatory requirements identified
B8: GOVERN | C8: Organizational Context | D8: GV.OC-03 | E8: Critical objectives and capabilities identified
B9: GOVERN | C9: Organizational Context | D9: GV.OC-04 | E9: Relationships and dependencies understood
B10: GOVERN | C10: Organizational Context | D10: GV.OC-05 | E10: Cybersecurity integrated into organizational strategy
B11: GOVERN | C11: Risk Management Strategy | D11: GV.RM-01 | E11: Risk management objectives established
B12: GOVERN | C12: Risk Management Strategy | D12: GV.RM-02 | E12: Risk appetite and tolerance determined
B13: GOVERN | C13: Risk Management Strategy | D13: GV.RM-03 | E13: Cybersecurity risk integrated into ERM
B14: GOVERN | C14: Risk Management Strategy | D14: GV.RM-04 | E14: Strategic direction communicated to stakeholders
B15: GOVERN | C15: Risk Management Strategy | D15: GV.RM-05 | E15: Threats and vulnerabilities fed into risk management
B16: GOVERN | C16: Risk Management Strategy | D16: GV.RM-06 | E16: Policies establish risk oversight responsibilities
B17: GOVERN | C17: Risk Management Strategy | D17: GV.RM-07 | E17: Strategic opportunities considered in risk decisions
... B36: GOVERN | C36: Supply Chain Risk Management | D36: GV.SC-10 | E36: Supply chain effectiveness reviewed
B38: ▶ IDENTIFY (ID)
B39: IDENTIFY | C39: Asset Management | D39: ID.AM-01 | E39: Hardware asset inventory maintained
B40: IDENTIFY | C40: Asset Management | D40: ID.AM-02 | E40: Software asset inventory maintained
B41: IDENTIFY | C41: Asset Management | D41: ID.AM-03 | E41: Network and data flow inventory maintained
B42: IDENTIFY | C42: Asset Management | D42: ID.AM-04 | E42: Service inventory maintained
B43: IDENTIFY | C43: Asset Management | D43: ID.AM-05 | E43: Assets prioritized by criticality
B44: IDENTIFY | C44: Asset Management | D44: ID.AM-07 | E44: Data and data types inventoried
B45: IDENTIFY | C45: Asset Management | D45: ID.AM-08 | E45: Assets managed through lifecycle
B46: IDENTIFY | C46: Risk Assessment | D46: ID.RA-01 | E46: Vulnerabilities identified and validated
B47: IDENTIFY | C47: Risk Assessment | D47: ID.RA-02 | E47: Threat intelligence received
B48: IDENTIFY | C48: Risk Assessment | D48: ID.RA-03 | E48: Internal/external threats identified
B49: IDENTIFY | C49: Risk Assessment | D49: ID.RA-04 | E49: Impacts and likelihoods considered
B50: IDENTIFY | C50: Risk Assessment | D50: ID.RA-05 | E50: Risk understood from threats/vulnerabilities
... B59: IDENTIFY | C59: Improvement | D59: ID.IM-04 | E59: Incident response evaluated and documented
B61: ▶ PROTECT (PR)
B62: PROTECT | C62: Identity Mgmt, Auth & Access Control | D62: PR.AA-01 | E62: User, service, and hardware identities managed
B63: PROTECT | C63: Identity Mgmt, Auth & Access Control | D63: PR.AA-02 | E63: Identities proofed and bound to credentials
B64: PROTECT | C64: Identity Mgmt, Auth & Access Control | D64: PR.AA-03 | E64: Users and services authenticated (MFA)
B65: PROTECT | C65: Identity Mgmt, Auth & Access Control | D65: PR.AA-04 | E65: Identity assertions protected
B66: PROTECT | C66: Identity Mgmt, Auth & Access Control | D66: PR.AA-05 | E66: Access permissions and authorizations managed
B67: PROTECT | C67: Identity Mgmt, Auth & Access Control | D67: PR.AA-06 | E67: Physical access controlled
B68: PROTECT | C68: Awareness and Training | D68: PR.AT-01 | E68: Awareness and training provided to all personnel
...

Sheet Target Profile
B1: NIST CSF 2.0 — Target Profile
B2: Organization: | G2: Date:
B3: Function | C3: Category | D3: Subcategory ID | E3: Subcategory Description | F3: Target Score | G3: Target Score | H3: Notes / Evidence Reference
E4: Enter desired target implementation score 1=Partial 2=Risk Informed 3=Repeatable 4=Adaptive | F4: Enter 1–4 (or N/A) | G4: Enter 1–4 (or N/A) | H4: Document evidence or context
B5: ▶ GOVERN (GV)
B6: GOVERN | C6: Organizational Context | D6: GV.OC-01 | E6: Mission, stakeholders, and dependencies understood
B7: GOVERN | C7: Organizational Context | D7: GV.OC-02 | E7: Legal/regulatory requirements identified
B8: GOVERN | C8: Organizational Context | D8: GV.OC-03 | E8: Critical objectives and capabilities identified
B9: GOVERN | C9: Organizational Context | D9: GV.OC-04 | E9: Relationships and dependencies understood
B10: GOVERN | C10: Organizational Context | D10: GV.OC-05 | E10: Cybersecurity integrated into organizational strategy
B11: GOVERN | C11: Risk Management Strategy | D11: GV.RM-01 | E11: Risk management objectives established
B12: GOVERN | C12: Risk Management Strategy | D12: GV.RM-02 | E12: Risk appetite and tolerance determined
B13: GOVERN | C13: Risk Management Strategy | D13: GV.RM-03 | E13: Cybersecurity risk integrated into ERM
B14: GOVERN | C14: Risk Management Strategy | D14: GV.RM-04 | E14: Strategic direction communicated to stakeholders
B15: GOVERN | C15: Risk Management Strategy | D15: GV.RM-05 | E15: Threats and vulnerabilities fed into risk management
B16: GOVERN | C16: Risk Management Strategy | D16: GV.RM-06 | E16: Policies establish risk oversight responsibilities
B17: GOVERN | C17: Risk Management Strategy | D17: GV.RM-07 | E17: Strategic opportunities considered in risk decisions
... B36: GOVERN | C36: Supply Chain Risk Management | D36: GV.SC-10 | E36: Supply chain effectiveness reviewed
B38: ▶ IDENTIFY (ID)
B39: IDENTIFY | C39: Asset Management | D39: ID.AM-01 | E39: Hardware asset inventory maintained
B40: IDENTIFY | C40: Asset Management | D40: ID.AM-02 | E40: Software asset inventory maintained
B41: IDENTIFY | C41: Asset Management | D41: ID.AM-03 | E41: Network and data flow inventory maintained
B42: IDENTIFY | C42: Asset Management | D42: ID.AM-04 | E42: Service inventory maintained
B43: IDENTIFY | C43: Asset Management | D43: ID.AM-05 | E43: Assets prioritized by criticality
B44: IDENTIFY | C44: Asset Management | D44: ID.AM-07 | E44: Data and data types inventoried
B45: IDENTIFY | C45: Asset Management | D45: ID.AM-08 | E45: Assets managed through lifecycle
B46: IDENTIFY | C46: Risk Assessment | D46: ID.RA-01 | E46: Vulnerabilities identified and validated
B47: IDENTIFY | C47: Risk Assessment | D47: ID.RA-02 | E47: Threat intelligence received
B48: IDENTIFY | C48: Risk Assessment | D48: ID.RA-03 | E48: Internal/external threats identified
B49: IDENTIFY | C49: Risk Assessment | D49: ID.RA-04 | E49: Impacts and likelihoods considered
B50: IDENTIFY | C50: Risk Assessment | D50: ID.RA-05 | E50: Risk understood from threats/vulnerabilities
... B59: IDENTIFY | C59: Improvement | D59: ID.IM-04 | E59: Incident response evaluated and documented
B61: ▶ PROTECT (PR)
B62: PROTECT | C62: Identity Mgmt, Auth & Access Control | D62: PR.AA-01 | E62: User, service, and hardware identities managed
B63: PROTECT | C63: Identity Mgmt, Auth & Access Control | D63: PR.AA-02 | E63: Identities proofed and bound to credentials
B64: PROTECT | C64: Identity Mgmt, Auth & Access Control | D64: PR.AA-03 | E64: Users and services authenticated (MFA)
B65: PROTECT | C65: Identity Mgmt, Auth & Access Control | D65: PR.AA-04 | E65: Identity assertions protected
B66: PROTECT | C66: Identity Mgmt, Auth & Access Control | D66: PR.AA-05 | E66: Access permissions and authorizations managed
B67: PROTECT | C67: Identity Mgmt, Auth & Access Control | D67: PR.AA-06 | E67: Physical access controlled
B68: PROTECT | C68: Awareness and Training | D68: PR.AT-01 | E68: Awareness and training provided to all personnel
...

Sheet Gap Analysis
B1: NIST CSF 2.0 — Gap Analysis (Auto-Calculated)
B2: Gaps are automatically calculated from Current Profile and Target Profile sheets. Positive gap = remediation needed.
B3: Function | C3: Subcategory ID | D3: Subcategory Description | E3: Current Score | F3: Target Score | G3: Gap | H3: Priority | I3: Recommended Action
B4: ▶ GOVERN (GV)
B5: GOVERN | C5: GV.OC-01 | D5: Mission, stakeholders, and dependencies understood | E5: ='Current Profile'!F6 | F5: ='Target Profile'!F6 | G5: =IF(ISNUMBER('Target Profile'!F6)*ISNUMBER('Current Profile'!F6),'Target Profile'!F6-'Current Profile'!F6,"") | H5: =IF(G5="","",IF(G5>=3,"🔴 Critical",IF(G5=2,"🟠 High",IF(G5=1,"🟡 Medium","✅ None"))))
B6: GOVERN | C6: GV.OC-02 | D6: Legal/regulatory requirements identified | E6: ='Current Profile'!F7 | F6: ='Target Profile'!F7 | G6: =IF(ISNUMBER('Target Profile'!F7)*ISNUMBER('Current Profile'!F7),'Target Profile'!F7-'Current Profile'!F7,"") | H6: =IF(G6="","",IF(G6>=3,"🔴 Critical",IF(G6=2,"🟠 High",IF(G6=1,"🟡 Medium","✅ None"))))
B7: GOVERN | C7: GV.OC-03 | D7: Critical objectives and capabilities identified | E7: ='Current Profile'!F8 | F7: ='Target Profile'!F8 | G7: =IF(ISNUMBER('Target Profile'!F8)*ISNUMBER('Current Profile'!F8),'Target Profile'!F8-'Current Profile'!F8,"") | H7: =IF(G7="","",IF(G7>=3,"🔴 Critical",IF(G7=2,"🟠 High",IF(G7=1,"🟡 Medium","✅ None"))))
B8: GOVERN | C8: GV.OC-04 | D8: Relationships and dependencies understood | E8: ='Current Profile'!F9 | F8: ='Target Profile'!F9 | G8: =IF(ISNUMBER('Target Profile'!F9)*ISNUMBER('Current Profile'!F9),'Target Profile'!F9-'Current Profile'!F9,"") | H8: =IF(G8="","",IF(G8>=3,"🔴 Critical",IF(G8=2,"🟠 High",IF(G8=1,"🟡 Medium","✅ None"))))
B9: GOVERN | C9: GV.OC-05 | D9: Cybersecurity integrated into organizational strategy | E9: ='Current Profile'!F10 | F9: ='Target Profile'!F10 | G9: =IF(ISNUMBER('Target Profile'!F10)*ISNUMBER('Current Profile'!F10),'Target Profile'!F10-'Current Profile'!F10,"") | H9: =IF(G9="","",IF(G9>=3,"🔴 Critical",IF(G9=2,"🟠 High",IF(G9=1,"🟡 Medium","✅ None"))))
B10: GOVERN | C10: GV.RM-01 | D10: Risk management objectives established | E10: ='Current Profile'!F11 | F10: ='Target Profile'!F11 | G10: =IF(ISNUMBER('Target Profile'!F11)*ISNUMBER('Current Profile'!F11),'Target Profile'!F11-'Current Profile'!F11,"") | H10: =IF(G10="","",IF(G10>=3,"🔴 Critical",IF(G10=2,"🟠 High",IF(G10=1,"🟡 Medium","✅ None"))))
B11: GOVERN | C11: GV.RM-02 | D11: Risk appetite and tolerance determined | E11: ='Current Profile'!F12 | F11: ='Target Profile'!F12 | G11: =IF(ISNUMBER('Target Profile'!F12)*ISNUMBER('Current Profile'!F12),'Target Profile'!F12-'Current Profile'!F12,"") | H11: =IF(G11="","",IF(G11>=3,"🔴 Critical",IF(G11=2,"🟠 High",IF(G11=1,"🟡 Medium","✅ None"))))
B12: GOVERN | C12: GV.RM-03 | D12: Cybersecurity risk integrated into ERM | E12: ='Current Profile'!F13 | F12: ='Target Profile'!F13 | G12: =IF(ISNUMBER('Target Profile'!F13)*ISNUMBER('Current Profile'!F13),'Target Profile'!F13-'Current Profile'!F13,"") | H12: =IF(G12="","",IF(G12>=3,"🔴 Critical",IF(G12=2,"🟠 High",IF(G12=1,"🟡 Medium","✅ None"))))
B13: GOVERN | C13: GV.RM-04 | D13: Strategic direction communicated to stakeholders | E13: ='Current Profile'!F14 | F13: ='Target Profile'!F14 | G13: =IF(ISNUMBER('Target Profile'!F14)*ISNUMBER('Current Profile'!F14),'Target Profile'!F14-'Current Profile'!F14,"") | H13: =IF(G13="","",IF(G13>=3,"🔴 Critical",IF(G13=2,"🟠 High",IF(G13=1,"🟡 Medium","✅ None"))))
B14: GOVERN | C14: GV.RM-05 | D14: Threats and vulnerabilities fed into risk management | E14: ='Current Profile'!F15 | F14: ='Target Profile'!F15 | G14: =IF(ISNUMBER('Target Profile'!F15)*ISNUMBER('Current Profile'!F15),'Target Profile'!F15-'Current Profile'!F15,"") | H14: =IF(G14="","",IF(G14>=3,"🔴 Critical",IF(G14=2,"🟠 High",IF(G14=1,"🟡 Medium","✅ None"))))
B15: GOVERN | C15: GV.RM-06 | D15: Policies establish risk oversight responsibilities | E15: ='Current Profile'!F16 | F15: ='Target Profile'!F16 | G15: =IF(ISNUMBER('Target Profile'!F16)*ISNUMBER('Current Profile'!F16),'Target Profile'!F16-'Current Profile'!F16,"") | H15: =IF(G15="","",IF(G15>=3,"🔴 Critical",IF(G15=2,"🟠 High",IF(G15=1,"🟡 Medium","✅ None"))))
B16: GOVERN | C16: GV.RM-07 | D16: Strategic opportunities considered in risk decisions | E16: ='Current Profile'!F17 | F16: ='Target Profile'!F17 | G16: =IF(ISNUMBER('Target Profile'!F17)*ISNUMBER('Current Profile'!F17),'Target Profile'!F17-'Current Profile'!F17,"") | H16: =IF(G16="","",IF(G16>=3,"🔴 Critical",IF(G16=2,"🟠 High",IF(G16=1,"🟡 Medium","✅ None"))))
... B35: GOVERN | C35: GV.SC-10 | D35: Supply chain effectiveness reviewed | E35: ='Current Profile'!F36 | F35: ='Target Profile'!F36 | G35: =IF(ISNUMBER('Target Profile'!F36)*ISNUMBER('Current Profile'!F36),'Target Profile'!F36-'Current Profile'!F36,"") | H35: =IF(G35="","",IF(G35>=3,"🔴 Critical",IF(G35=2,"🟠 High",IF(G35=1,"🟡 Medium","✅ None"))))
B37: ▶ IDENTIFY (ID)
B38: IDENTIFY | C38: ID.AM-01 | D38: Hardware asset inventory maintained | E38: ='Current Profile'!F39 | F38: ='Target Profile'!F39 | G38: =IF(ISNUMBER('Target Profile'!F39)*ISNUMBER('Current Profile'!F39),'Target Profile'!F39-'Current Profile'!F39,"") | H38: =IF(G38="","",IF(G38>=3,"🔴 Critical",IF(G38=2,"🟠 High",IF(G38=1,"🟡 Medium","✅ None"))))
B39: IDENTIFY | C39: ID.AM-02 | D39: Software asset inventory maintained | E39: ='Current Profile'!F40 | F39: ='Target Profile'!F40 | G39: =IF(ISNUMBER('Target Profile'!F40)*ISNUMBER('Current Profile'!F40),'Target Profile'!F40-'Current Profile'!F40,"") | H39: =IF(G39="","",IF(G39>=3,"🔴 Critical",IF(G39=2,"🟠 High",IF(G39=1,"🟡 Medium","✅ None"))))
B40: IDENTIFY | C40: ID.AM-03 | D40: Network and data flow inventory maintained | E40: ='Current Profile'!F41 | F40: ='Target Profile'!F41 | G40: =IF(ISNUMBER('Target Profile'!F41)*ISNUMBER('Current Profile'!F41),'Target Profile'!F41-'Current Profile'!F41,"") | H40: =IF(G40="","",IF(G40>=3,"🔴 Critical",IF(G40=2,"🟠 High",IF(G40=1,"🟡 Medium","✅ None"))))
B41: IDENTIFY | C41: ID.AM-04 | D41: Service inventory maintained | E41: ='Current Profile'!F42 | F41: ='Target Profile'!F42 | G41: =IF(ISNUMBER('Target Profile'!F42)*ISNUMBER('Current Profile'!F42),'Target Profile'!F42-'Current Profile'!F42,"") | H41: =IF(G41="","",IF(G41>=3,"🔴 Critical",IF(G41=2,"🟠 High",IF(G41=1,"🟡 Medium","✅ None"))))
B42: IDENTIFY | C42: ID.AM-05 | D42: Assets prioritized by criticality | E42: ='Current Profile'!F43 | F42: ='Target Profile'!F43 | G42: =IF(ISNUMBER('Target Profile'!F43)*ISNUMBER('Current Profile'!F43),'Target Profile'!F43-'Current Profile'!F43,"") | H42: =IF(G42="","",IF(G42>=3,"🔴 Critical",IF(G42=2,"🟠 High",IF(G42=1,"🟡 Medium","✅ None"))))
B43: IDENTIFY | C43: ID.AM-07 | D43: Data and data types inventoried | E43: ='Current Profile'!F44 | F43: ='Target Profile'!F44 | G43: =IF(ISNUMBER('Target Profile'!F44)*ISNUMBER('Current Profile'!F44),'Target Profile'!F44-'Current Profile'!F44,"") | H43: =IF(G43="","",IF(G43>=3,"🔴 Critical",IF(G43=2,"🟠 High",IF(G43=1,"🟡 Medium","✅ None"))))
B44: IDENTIFY | C44: ID.AM-08 | D44: Assets managed through lifecycle | E44: ='Current Profile'!F45 | F44: ='Target Profile'!F45 | G44: =IF(ISNUMBER('Target Profile'!F45)*ISNUMBER('Current Profile'!F45),'Target Profile'!F45-'Current Profile'!F45,"") | H44: =IF(G44="","",IF(G44>=3,"🔴 Critical",IF(G44=2,"🟠 High",IF(G44=1,"🟡 Medium","✅ None"))))
B45: IDENTIFY | C45: ID.RA-01 | D45: Vulnerabilities identified and validated | E45: ='Current Profile'!F46 | F45: ='Target Profile'!F46 | G45: =IF(ISNUMBER('Target Profile'!F46)*ISNUMBER('Current Profile'!F46),'Target Profile'!F46-'Current Profile'!F46,"") | H45: =IF(G45="","",IF(G45>=3,"🔴 Critical",IF(G45=2,"🟠 High",IF(G45=1,"🟡 Medium","✅ None"))))
B46: IDENTIFY | C46: ID.RA-02 | D46: Threat intelligence received | E46: ='Current Profile'!F47 | F46: ='Target Profile'!F47 | G46: =IF(ISNUMBER('Target Profile'!F47)*ISNUMBER('Current Profile'!F47),'Target Profile'!F47-'Current Profile'!F47,"") | H46: =IF(G46="","",IF(G46>=3,"🔴 Critical",IF(G46=2,"🟠 High",IF(G46=1,"🟡 Medium","✅ None"))))
B47: IDENTIFY | C47: ID.RA-03 | D47: Internal/external threats identified | E47: ='Current Profile'!F48 | F47: ='Target Profile'!F48 | G47: =IF(ISNUMBER('Target Profile'!F48)*ISNUMBER('Current Profile'!F48),'Target Profile'!F48-'Current Profile'!F48,"") | H47: =IF(G47="","",IF(G47>=3,"🔴 Critical",IF(G47=2,"🟠 High",IF(G47=1,"🟡 Medium","✅ None"))))
B48: IDENTIFY | C48: ID.RA-04 | D48: Impacts and likelihoods considered | E48: ='Current Profile'!F49 | F48: ='Target Profile'!F49 | G48: =IF(ISNUMBER('Target Profile'!F49)*ISNUMBER('Current Profile'!F49),'Target Profile'!F49-'Current Profile'!F49,"") | H48: =IF(G48="","",IF(G48>=3,"🔴 Critical",IF(G48=2,"🟠 High",IF(G48=1,"🟡 Medium","✅ None"))))
B49: IDENTIFY | C49: ID.RA-05 | D49: Risk understood from threats/vulnerabilities | E49: ='Current Profile'!F50 | F49: ='Target Profile'!F50 | G49: =IF(ISNUMBER('Target Profile'!F50)*ISNUMBER('Current Profile'!F50),'Target Profile'!F50-'Current Profile'!F50,"") | H49: =IF(G49="","",IF(G49>=3,"🔴 Critical",IF(G49=2,"🟠 High",IF(G49=1,"🟡 Medium","✅ None"))))
... B58: IDENTIFY | C58: ID.IM-04 | D58: Incident response evaluated and documented | E58: ='Current Profile'!F59 | F58: ='Target Profile'!F59 | G58: =IF(ISNUMBER('Target Profile'!F59)*ISNUMBER('Current Profile'!F59),'Target Profile'!F59-'Current Profile'!F59,"") | H58: =IF(G58="","",IF(G58>=3,"🔴 Critical",IF(G58=2,"🟠 High",IF(G58=1,"🟡 Medium","✅ None"))))
B60: ▶ PROTECT (PR)
B61: PROTECT | C61: PR.AA-01 | D61: User, service, and hardware identities managed | E61: ='Current Profile'!F62 | F61: ='Target Profile'!F62 | G61: =IF(ISNUMBER('Target Profile'!F62)*ISNUMBER('Current Profile'!F62),'Target Profile'!F62-'Current Profile'!F62,"") | H61: =IF(G61="","",IF(G61>=3,"🔴 Critical",IF(G61=2,"🟠 High",IF(G61=1,"🟡 Medium","✅ None"))))
B62: PROTECT | C62: PR.AA-02 | D62: Identities proofed and bound to credentials | E62: ='Current Profile'!F63 | F62: ='Target Profile'!F63 | G62: =IF(ISNUMBER('Target Profile'!F63)*ISNUMBER('Current Profile'!F63),'Target Profile'!F63-'Current Profile'!F63,"") | H62: =IF(G62="","",IF(G62>=3,"🔴 Critical",IF(G62=2,"🟠 High",IF(G62=1,"🟡 Medium","✅ None"))))
B63: PROTECT | C63: PR.AA-03 | D63: Users and services authenticated (MFA) | E63: ='Current Profile'!F64 | F63: ='Target Profile'!F64 | G63: =IF(ISNUMBER('Target Profile'!F64)*ISNUMBER('Current Profile'!F64),'Target Profile'!F64-'Current Profile'!F64,"") | H63: =IF(G63="","",IF(G63>=3,"🔴 Critical",IF(G63=2,"🟠 High",IF(G63=1,"🟡 Medium","✅ None"))))
B64: PROTECT | C64: PR.AA-04 | D64: Identity assertions protected | E64: ='Current Profile'!F65 | F64: ='Target Profile'!F65 | G64: =IF(ISNUMBER('Target Profile'!F65)*ISNUMBER('Current Profile'!F65),'Target Profile'!F65-'Current Profile'!F65,"") | H64: =IF(G64="","",IF(G64>=3,"🔴 Critical",IF(G64=2,"🟠 High",IF(G64=1,"🟡 Medium","✅ None"))))
B65: PROTECT | C65: PR.AA-05 | D65: Access permissions and authorizations managed | E65: ='Current Profile'!F66 | F65: ='Target Profile'!F66 | G65: =IF(ISNUMBER('Target Profile'!F66)*ISNUMBER('Current Profile'!F66),'Target Profile'!F66-'Current Profile'!F66,"") | H65: =IF(G65="","",IF(G65>=3,"🔴 Critical",IF(G65=2,"🟠 High",IF(G65=1,"🟡 Medium","✅ None"))))
B66: PROTECT | C66: PR.AA-06 | D66: Physical access controlled | E66: ='Current Profile'!F67 | F66: ='Target Profile'!F67 | G66: =IF(ISNUMBER('Target Profile'!F67)*ISNUMBER('Current Profile'!F67),'Target Profile'!F67-'Current Profile'!F67,"") | H66: =IF(G66="","",IF(G66>=3,"🔴 Critical",IF(G66=2,"🟠 High",IF(G66=1,"🟡 Medium","✅ None"))))
B67: PROTECT | C67: PR.AT-01 | D67: Awareness and training provided to all personnel | E67: ='Current Profile'!F68 | F67: ='Target Profile'!F68 | G67: =IF(ISNUMBER('Target Profile'!F68)*ISNUMBER('Current Profile'!F68),'Target Profile'!F68-'Current Profile'!F68,"") | H67: =IF(G67="","",IF(G67>=3,"🔴 Critical",IF(G67=2,"🟠 High",IF(G67=1,"🟡 Medium","✅ None"))))
B68: PROTECT | C68: PR.AT-02 | D68: Specialized role training provided | E68: ='Current Profile'!F69 | F68: ='Target Profile'!F69 | G68: =IF(ISNUMBER('Target Profile'!F69)*ISNUMBER('Current Profile'!F69),'Target Profile'!F69-'Current Profile'!F69,"") | H68: =IF(G68="","",IF(G68>=3,"🔴 Critical",IF(G68=2,"🟠 High",IF(G68=1,"🟡 Medium","✅ None"))))
...

Sheet Tier Summary
B1: NIST CSF 2.0 — Tier Summary Dashboard
B2: Scores are drawn automatically from the Gap Analysis sheet. This view is for leadership reporting.
B3: Function | C3: Current Avg Score | D3: Target Avg Score | E3: Current Tier | F3: Status
B4: GOVERN (GV) | C4: =IFERROR(AVERAGE('Gap Analysis'!E5:E35),"") | D4: =IFERROR(AVERAGE('Gap Analysis'!F5:F35),"") | E4: =IF(ISNUMBER(C4),INT(C4),"") | F4: =IF(C4="","Not Assessed",IF(C4>=D4,"✅ On Target",IF(D4-C4>=2,"🔴 Significant Gap","🟡 Gap")))
B5: IDENTIFY (ID) | C5: =IFERROR(AVERAGE('Gap Analysis'!E38:E58),"") | D5: =IFERROR(AVERAGE('Gap Analysis'!F38:F58),"") | E5: =IF(ISNUMBER(C5),INT(C5),"") | F5: =IF(C5="","Not Assessed",IF(C5>=D5,"✅ On Target",IF(D5-C5>=2,"🔴 Significant Gap","🟡 Gap")))
B6: PROTECT (PR) | C6: =IFERROR(AVERAGE('Gap Analysis'!E61:E82),"") | D6: =IFERROR(AVERAGE('Gap Analysis'!F61:F82),"") | E6: =IF(ISNUMBER(C6),INT(C6),"") | F6: =IF(C6="","Not Assessed",IF(C6>=D6,"✅ On Target",IF(D6-C6>=2,"🔴 Significant Gap","🟡 Gap")))
B7: DETECT (DE) | C7: =IFERROR(AVERAGE('Gap Analysis'!E85:E95),"") | D7: =IFERROR(AVERAGE('Gap Analysis'!F85:F95),"") | E7: =IF(ISNUMBER(C7),INT(C7),"") | F7: =IF(C7="","Not Assessed",IF(C7>=D7,"✅ On Target",IF(D7-C7>=2,"🔴 Significant Gap","🟡 Gap")))
B8: RESPOND (RS) | C8: =IFERROR(AVERAGE('Gap Analysis'!E98:E110),"") | D8: =IFERROR(AVERAGE('Gap Analysis'!F98:F110),"") | E8: =IF(ISNUMBER(C8),INT(C8),"") | F8: =IF(C8="","Not Assessed",IF(C8>=D8,"✅ On Target",IF(D8-C8>=2,"🔴 Significant Gap","🟡 Gap")))
B9: RECOVER (RC) | C9: =IFERROR(AVERAGE('Gap Analysis'!E113:E120),"") | D9: =IFERROR(AVERAGE('Gap Analysis'!F113:F120),"") | E9: =IF(ISNUMBER(C9),INT(C9),"") | F9: =IF(C9="","Not Assessed",IF(C9>=D9,"✅ On Target",IF(D9-C9>=2,"🔴 Significant Gap","🟡 Gap")))
B11: Overall Program Tier | C11: =IFERROR(MIN(INT(C4),INT(C5),INT(C6),INT(C7),INT(C8),INT(C9)),"") | D11: =IFERROR(MIN(INT(D4),INT(D5),INT(D6),INT(D7),INT(D8),INT(D9)),"")
B13: Tier Reference
B14: Tier 1 | C14: Partial | D14: Risk practices are ad hoc, reactive, and not formalized
B15: Tier 2 | C15: Risk Informed | D15: Risk awareness exists but not applied organization-wide
B16: Tier 3 | C16: Repeatable | D16: Risk practices are formally approved and consistently applied
B17: Tier 4 | C17: Adaptive | D17: Risk practices continuously improved based on threat intelligence
